Workbook

Sheet country_world_globalpetrolprice
A1: fid | B1: NAME_EN | C1: NAME_RU | D1: Потребление нефти/нефтепродуктов, барр./сут. | E1: Год потребления | F1: Потребление, млн барр./год | G1: Дизель/дистилляты, % потребления | H1: Бензин, % потребления | I1: LPG, % потребления | J1: Jet/керосин, % потребления | K1: Мазут/Residual Fuel Oil, % потребления | L1: Добыча нефти и жидкостей, барр./сут. | M1: Год добычи | N1: Добыча сырой нефти, барр./сут. | O1: Добыча NGPL, барр./сут. | P1: ВВП, млрд USD | Q1: Год ВВП | R1: Рост ВВП, % | S1: Год роста | T1: Инфляция CPI, % | U1: Год инфляции | V1: Цена бензина, USD | W1: Цена дизеля, USD | X1: Цена Jet/керосина, USD | Y1: Цена LPG, USD | Z1: Цена мазута, USD | AA1: Единица/тип цены | AB1: Дата цены | AC1: Источник нефть/нефтепродукты | AD1: Источник экономика | AE1: Источник цены | AF1: Комментарий | AG1: Статус цены топлива | AH1: ISO2 | AI1: ISO3 | AJ1: НПЗ Oilmap, шт. | AK1: Известная мощность Oilmap, барр./сут. | AL1: НПЗ Oilmap без мощности, шт. | AM1: Дата слоя Oilmap | AN1: НПЗ: статус свежей проверки | AO1: Год продуктовых долей | AP1: Год сырой нефти / конденсата | AQ1: Год NGPL | AR1: Дата проверки
A2: 1 | B2: Indonesia | C2: Индонезия | D2: 2153449.3 | E2: 2025 | F2: =IF(AND(ISNUMBER(D2),ISNUMBER(E2)),D2*(DATE(E2+1,1,1)-DATE(E2,1,1))/1000000,"н/д") -> 786.009 | G2: 31.704726 | H2: 30.451941 | I2: 14.642962 | J2: 7.8304447 | K2: 1.5610508 | L2: 852688.87 | M2: 2025 | N2: 581668.49 | O2: 20000 | P2: 1445.6426 | Q2: 2025 | R2: 5.108089 | S2: 2025 | T2: 1.9133344 | U2: 2025 | V2: 0.939 | W2: 1.438 | X2: н/д | Y2: н/д | Z2: н/д | AA2: Бензин/дизель/LPG: USD/л; Jet/мазут: исходные единицы | AB2: Бензин: 2026-09-14; Дизель: 2026-09-14; исходные даты для непроверенных значений: бензин: 2026-09-14; дизель/LPG: 2026-09-07; Jet/мазут: н/д | AC2: https://api.eia.gov/v2/international/data/?frequency=annual&facets[productId][]=53&facets[activityId][]=1&facets[unit][]=TBPD ; https://api.eia.gov/v2/international/data/?frequency=annual&facets[productId][]=57&facets[activityId][]=1&facets[unit][]=TBPD ; https://api.eia.gov/v2/international/data/?frequency=annual&facets[productId][]=58&facets[activityId][]=1&facets[unit][]=TBPD ; https://www.jodidata.org/_resources/files/downloads/oil-data/annual-csv/secondary/2025.csv ; Исходный источник: https://www.jodidata.org/oil/database/data-downloads.aspx ; https://www.worldometers.info/oil/indonesia-oil/ | AD2: https://api.worldbank.org/v2/country/IDN/indicator/NY.GDP.MKTP.CD?format=json ; https://api.worldbank.org/v2/country/IDN/indicator/NY.GDP.MKTP.KD.ZG?format=json ; https://api.worldbank.org/v2/country/IDN/indicator/FP.CPI.TOTL.ZG?format=json ; Исходный источник: https://data.worldbank.org/ | AE2: https://www.globalpetrolprices.com/Indonesia/gasoline_prices/ ; https://www.globalpetrolprices.com/Indonesia/diesel_prices/ ; Исходный источник: GlobalPetrolPrices (страновые значения только там, где они были явно помечены как страновые); Jet/мазут: н/д | AF2: Массовые оценки/медианы удалены в ходе аудита. Сохранившиеся исходные числовые значения не считаются подтверждёнными автоматически; требуется первичная проверка источника. Обновление 16.09.2026: Потребление и доли: JODI, нефтепродукты TOTPRODS, 12 месяцев 2025. Jet/мазут: национальные сопоставимые цены не найдены; исходные значения сохранены. | AG2: Бензин: проверено GPP; Дизель: проверено GPP; LPG: н/д; Jet/керосин: нет сопоставимой национальной цены; Мазут: нет сопоставимой национальной цены | AH2: ID | AI2: IDN | AJ2: ='Сводка НПЗ'!D2 -> 8 | AK2: =IF('Сводка НПЗ'!F2>0,'Сводка НПЗ'!E2,"") -> 1046370 | AL2: ='Сводка НПЗ'!G2 -> 0 | AM2: 2019-02-18 | AN2: Мощность: вторичная публикация EI; число НПЗ не подтверждено | AO2: 2025 | AP2: 2025 | AQ2: 2025 | AR2: 2026-09-16
A3: 2 | B3: Malaysia | C3: Малайзия | D3: 747111.57 | E3: 2024 | F3: =IF(AND(ISNUMBER(D3),ISNUMBER(E3)),D3*(DATE(E3+1,1,1)-DATE(E3,1,1))/1000000,"н/д") -> 273.44283 | G3: 26.813777 | H3: 43.478961 | I3: 11.014423 | J3: 7.1779446 | K3: 3.2695489 | L3: 604170.9 | M3: 2025 | N3: 512670.14 | O3: 39578.995 | P3: 472.19313 | Q3: 2025 | R3: 5.1712708 | S3: 2025 | T3: 1.3806087 | U3: 2025 | V3: 0.994 | W3: 1.216 | X3: н/д | Y3: н/д | Z3: н/д | AA3: Бензин/дизель/LPG: USD/л; Jet/мазут: исходные единицы | AB3: Бензин: 2026-09-14; Дизель: 2026-09-14; исходные даты для непроверенных значений: бензин: 2026-09-14; дизель/LPG: 2026-09-07; Jet/мазут: н/д | AC3: https://api.eia.gov/v2/international/data/?frequency=annual&facets[productId][]=53&facets[activityId][]=1&facets[unit][]=TBPD ; https://api.eia.gov/v2/international/data/?frequency=annual&facets[productId][]=57&facets[activityId][]=1&facets[unit][]=TBPD ; https://api.eia.gov/v2/international/data/?frequency=annual&facets[productId][]=58&facets[activityId][]=1&facets[unit][]=TBPD ; https://api.eia.gov/v2/international/data/?frequency=annual&facets[productId][]=5&facets[activityId][]=2&facets[unit][]=TBPD ; Исходный источник: https://www.jodidata.org/oil/database/data-downloads.aspx ; https://www.worldometers.info/oil/malaysia-oil/ | AD3: https://api.worldbank.org/v2/country/MYS/indicator/NY.GDP.MKTP.CD?format=json ; https://api.worldbank.org/v2/country/MYS/indicator/NY.GDP.MKTP.KD.ZG?format=json ; https://api.worldbank.org/v2/country/MYS/indicator/FP.CPI.TOTL.ZG?format=json ; Исходный источник: https://data.worldbank.org/ | AE3: https://www.globalpetrolprices.com/Malaysia/gasoline_prices/ ; https://www.globalpetrolprices.com/Malaysia/diesel_prices/ ; Исходный источник: GlobalPetrolPrices (страновые значения только там, где они были явно помечены как страновые); Jet/мазут: н/д | AF3: Массовые оценки/медианы удалены в ходе аудита. Сохранившиеся исходные числовые значения не считаются подтверждёнными автоматически; требуется первичная проверка источника. Обновление 16.09.2026: Потребление и доли: EIA, petroleum and other liquids, 2024; включает биотопливо. Jet/мазут: национальные сопоставимые цены не найдены; исходные значения сохранены. | AG3: Бензин: проверено GPP; Дизель: проверено GPP; LPG: н/д; Jet/керосин: нет сопоставимой национальной цены; Мазут: нет сопоставимой национальной цены | AH3: MY | AI3: MYS | AJ3: ='Сводка НПЗ'!D3 -> 6 | AK3: =IF('Сводка НПЗ'!F3>0,'Сводка НПЗ'!E3,"") -> 545000 | AL3: ='Сводка НПЗ'!G3 -> 0 | AM3: 2019-02-18 | AN3: Мощность: вторичная публикация EI; число НПЗ не подтверждено | AO3: 2024 | AP3: 2025 | AQ3: 2025 | AR3: 2026-09-16
A4: 3 | B4: Chile | C4: Чили | D4: 374295.89 | E4: 2025 | F4: =IF(AND(ISNUMBER(D4),ISNUMBER(E4)),D4*(DATE(E4+1,1,1)-DATE(E4,1,1))/1000000,"н/д") -> 136.618 | G4: 49.00205 | H4: 24.575751 | I4: 11.836068 | J4: 14.142434 | K4: 1.8786836 | L4: 21108.608 | M4: 2025 | N4: 1968.322 | O4: 11828.373 | P4: 357.37116 | Q4: 2025 | R4: 2.4592547 | S4: 2025 | T4: 4.212936 | U4: 2025 | V4: 1.522 | W4: 1.319 | X4: н/д | Y4: 0.715 | Z4: н/д | AA4: Бензин/дизель/LPG: USD/л; Jet/мазут: исходные единицы | AB4: Бензин: 2026-09-14; Дизель: 2026-09-14; LPG: 2026-09-14; исходные даты для непроверенных значений: бензин: 2026-09-14; дизель/LPG: 2026-09-07; Jet/мазут: н/д | AC4: https://api.eia.gov/v2/international/data/?frequency=annual&facets[productId][]=53&facets[activityId][]=1&facets[unit][]=TBPD ; https://api.eia.gov/v2/international/data/?frequency=annual&facets[productId][]=57&facets[activityId][]=1&facets[unit][]=TBPD ; https://api.eia.gov/v2/international/data/?frequency=annual&facets[productId][]=58&facets[activityId][]=1&facets[unit][]=TBPD ; https://www.jodidata.org/_resources/files/downloads/oil-data/annual-csv/secondary/2025.csv ; Исходный источник: https://www.jodidata.org/oil/database/data-downloads.aspx ; https://www.worldometers.info/oil/chile-oil/ | AD4: https://api.worldbank.org/v2/country/CHL/indicator/NY.GDP.MKTP.CD?format=json ; https://api.worldbank.org/v2/country/CHL/indicator/NY.GDP.MKTP.KD.ZG?format=json ; https://api.worldbank.org/v2/country/CHL/indicator/FP.CPI.TOTL.ZG?format=json ; Исходный источник: https://data.worldbank.org/ | AE4: https://www.globalpetrolprices.com/Chile/gasoline_prices/ ; https://www.globalpetrolprices.com/Chile/diesel_prices/ ; https://www.globalpetrolprices.com/Chile/lpg_prices/ ; Исходный источник: GlobalPetrolPrices (страновые значения только там, где они были явно помечены как страновые); Jet/мазут: н/д | AF4: Массовые оценки/медианы удалены в ходе аудита. Сохранившиеся исходные числовые значения не считаются подтверждёнными автоматически; требуется первичная проверка источника. Обновление 16.09.2026: Потребление и доли: JODI, нефтепродукты TOTPRODS, 12 месяцев 2025. Jet/мазут: национальные сопоставимые цены не найдены; исходные значения сохранены. | AG4: Бензин: проверено GPP; Дизель: проверено GPP; LPG: проверено GPP; Jet/керосин: нет сопоставимой национальной цены; Мазут: нет сопоставимой национальной цены | AH4: CL | AI4: CHL | AJ4: ='Сводка НПЗ'!D4 -> 3 | AK4: =IF('Сводка НПЗ'!F4>0,'Сводка НПЗ'!E4,"") -> 226750 | AL4: ='Сводка НПЗ'!G4 -> 0 | AM4: 2019-02-18 | AN4: Мощность: вторичная публикация EI; число НПЗ не подтверждено | AO4: 2025 | AP4: 2025 | AQ4: 2025 | AR4: 2026-09-16
A5: 4 | B5: Bolivia | C5: Боливия | D5: 103844.97 | E5: 2024 | F5: =IF(AND(ISNUMBER(D5),ISNUMBER(E5)),D5*(DATE(E5+1,1,1)-DATE(E5,1,1))/1000000,"н/д") -> 38.007258 | G5: 41.252249 | H5: 38.801499 | I5: 14.43811 | J5: 3.7013216 | K5: 0 | L5: 51865.89 | M5: 2025 | N5: 17660.805 | O5: 32000 | P5: 64.768948 | Q5: 2025 | R5: -1.5823757 | S5: 2025 | T5: 19.517121 | U5: 2025 | V5: 0.603 | W5: 0.85 | X5: н/д | Y5: н/д | Z5: н/д | AA5: Бензин/дизель/LPG: USD/л; Jet/мазут: исходные единицы | AB5: Бензин: 2026-09-14; Дизель: 2026-09-14; исходные даты для непроверенных значений: бензин: 2026-09-14; дизель/LPG: 2026-09-07; Jet/мазут: н/д | AC5: https://api.eia.gov/v2/international/data/?frequency=annual&facets[productId][]=53&facets[activityId][]=1&facets[unit][]=TBPD ; https://api.eia.gov/v2/international/data/?frequency=annual&facets[productId][]=57&facets[activityId][]=1&facets[unit][]=TBPD ; https://api.eia.gov/v2/international/data/?frequency=annual&facets[productId][]=58&facets[activityId][]=1&facets[unit][]=TBPD ; https://api.eia.gov/v2/international/data/?frequency=annual&facets[productId][]=5&facets[activityId][]=2&facets[unit][]=TBPD ; Исходный источник: https://www.jodidata.org/oil/database/data-downloads.aspx ; https://www.worldometers.info/oil/bolivia-oil/ | AD5: https://api.worldbank.org/v2/country/BOL/indicator/NY.GDP.MKTP.CD?format=json ; https://api.worldbank.org/v2/country/BOL/indicator/NY.GDP.MKTP.KD.ZG?format=json ; https://api.worldbank.org/v2/country/BOL/indicator/FP.CPI.TOTL.ZG?format=json ; Исходный источник: https://data.worldbank.org/ | AE5: https://www.globalpetrolprices.com/Bolivia/gasoline_prices/ ; https://www.globalpetrolprices.com/Bolivia/diesel_prices/ ; Исходный источник: GlobalPetrolPrices (страновые значения только там, где они были явно помечены как страновые); Jet/мазут: н/д | AF5: Массовые оценки/медианы удалены в ходе аудита. Сохранившиеся исходные числовые значения не считаются подтверждёнными автоматически; требуется первичная проверка источника. Обновление 16.09.2026: Потребление и доли: EIA, petroleum and other liquids, 2024; включает биотопливо. Jet/мазут: национальные сопоставимые цены не найдены; исходные значения сохранены. | AG5: Бензин: проверено GPP; Дизель: проверено GPP; LPG: н/д; Jet/керосин: нет сопоставимой национальной цены; Мазут: нет сопоставимой национальной цены | AH5: BO | AI5: BOL | AJ5: ='Сводка НПЗ'!D5 -> 2 | AK5: =IF('Сводка НПЗ'!F5>0,'Сводка НПЗ'!E5,"") -> 20000 | AL5: ='Сводка НПЗ'!G5 -> 1 | AM5: 2019-02-18 | AN5: Свежие число и мощность не подтверждены | AO5: 2024 | AP5: 2025 | AQ5: 2025 | AR5: 2026-09-16
A6: 5 | B6: Peru | C6: Перу | D6: 264380.45 | E6: 2024 | F6: =IF(AND(ISNUMBER(D6),ISNUMBER(E6)),D6*(DATE(E6+1,1,1)-DATE(E6,1,1))/1000000,"н/д") -> 96.763245 | G6: 41.462548 | H6: 19.301277 | I6: 27.160897 | J6: 5.8060151 | K6: 5.2555087 | L6: 123301.73 | M6: 2025 | N6: 44152.745 | O6: 73325.764 | P6: 334.85466 | Q6: 2025 | R6: 3.430564 | S6: 2025 | T6: 1.5312545 | U6: 2025 | V6: 1.723 | W6: 1.965 | X6: н/д | Y6: 0.642 | Z6: н/д | AA6: Бензин/дизель/LPG: USD/л; Jet/мазут: исходные единицы | AB6: Бензин: 2026-09-14; Дизель: 2026-09-14; LPG: 2026-09-14; исходные даты для непроверенных значений: бензин: 2026-09-14; дизель/LPG: 2026-09-07; Jet/мазут: н/д | AC6: https://api.eia.gov/v2/international/data/?frequency=annual&facets[productId][]=53&facets[activityId][]=1&facets[unit][]=TBPD ; https://api.eia.gov/v2/international/data/?frequency=annual&facets[productId][]=57&facets[activityId][]=1&facets[unit][]=TBPD ; https://api.eia.gov/v2/international/data/?frequency=annual&facets[productId][]=58&facets[activityId][]=1&facets[unit][]=TBPD ; https://api.eia.gov/v2/international/data/?frequency=annual&facets[productId][]=5&facets[activityId][]=2&facets[unit][]=TBPD ; Исходный источник: https://www.jodidata.org/oil/database/data-downloads.aspx ; https://www.worldometers.info/oil/peru-oil/ | AD6: https://api.worldbank.org/v2/country/PER/indicator/NY.GDP.MKTP.CD?format=json ; https://api.worldbank.org/v2/country/PER/indicator/NY.GDP.MKTP.KD.ZG?format=json ; https://api.worldbank.org/v2/country/PER/indicator/FP.CPI.TOTL.ZG?format=json ; Исходный источник: https://data.worldbank.org/ | AE6: https://www.globalpetrolprices.com/Peru/gasoline_prices/ ; https://www.globalpetrolprices.com/Peru/diesel_prices/ ; https://www.globalpetrolprices.com/Peru/lpg_prices/ ; Исходный источник: GlobalPetrolPrices (страновые значения только там, где они были явно помечены как страновые); Jet/мазут: н/д | AF6: Массовые оценки/медианы удалены в ходе аудита. Сохранившиеся исходные числовые значения не считаются подтверждёнными автоматически; требуется первичная проверка источника. Обновление 16.09.2026: Потребление и доли: EIA, petroleum and other liquids, 2024; включает биотопливо. Jet/мазут: национальные сопоставимые цены не найдены; исходные значения сохранены. | AG6: Бензин: проверено GPP; Дизель: проверено GPP; LPG: проверено GPP; Jet/керосин: нет сопоставимой национальной цены; Мазут: нет сопоставимой национальной цены | AH6: PE | AI6: PER | AJ6: ='Сводка НПЗ'!D6 -> 6 | AK6: =IF('Сводка НПЗ'!F6>0,'Сводка НПЗ'!E6,"") -> 165250 | AL6: ='Сводка НПЗ'!G6 -> 3 | AM6: 2019-02-18 | AN6: Мощность: вторичная публикация EI; число НПЗ не подтверждено | AO6: 2024 | AP6: 2025 | AQ6: 2025 | AR6: 2026-09-16
A7: 6 | B7: Argentina | C7: Аргентина | D7: 734572.71 | E7: 2024 | F7: =IF(AND(ISNUMBER(D7),ISNUMBER(E7)),D7*(DATE(E7+1,1,1)-DATE(E7,1,1))/1000000,"н/д") -> 268.85361 | G7: 29.76554 | H7: 26.23083 | I7: 7.3289834 | J7: 4.5606832 | K7: 1.9697892 | L7: 983537.17 | M7: 2025 | N7: 794004.45 | O7: 130000 | P7: 683.09789 | Q7: 2025 | R7: 4.3673333 | S7: 2025 | T7: 219.88393 | U7: 2024 | V7: 1.412 | W7: 1.518 | X7: н/д | Y7: н/д | Z7: н/д | AA7: Бензин/дизель/LPG: USD/л; Jet/мазут: исходные единицы | AB7: Бензин: 2026-09-14; Дизель: 2026-09-14; исходные даты для непроверенных значений: бензин: 2026-09-14; дизель/LPG: 2026-09-07; Jet/мазут: н/д | AC7: https://api.eia.gov/v2/international/data/?frequency=annual&facets[productId][]=53&facets[activityId][]=1&facets[unit][]=TBPD ; https://api.eia.gov/v2/international/data/?frequency=annual&facets[productId][]=57&facets[activityId][]=1&facets[unit][]=TBPD ; https://api.eia.gov/v2/international/data/?frequency=annual&facets[productId][]=58&facets[activityId][]=1&facets[unit][]=TBPD ; https://api.eia.gov/v2/international/data/?frequency=annual&facets[productId][]=5&facets[activityId][]=2&facets[unit][]=TBPD ; Исходный источник: https://www.jodidata.org/oil/database/data-downloads.aspx ; https://www.worldometers.info/oil/argentina-oil/ | AD7: https://api.worldbank.org/v2/country/ARG/indicator/NY.GDP.MKTP.CD?format=json ; https://api.worldbank.org/v2/country/ARG/indicator/NY.GDP.MKTP.KD.ZG?format=json ; https://api.worldbank.org/v2/country/ARG/indicator/FP.CPI.TOTL.ZG?format=json ; Исходный источник: https://data.worldbank.org/ | AE7: https://www.globalpetrolprices.com/Argentina/gasoline_prices/ ; https://www.globalpetrolprices.com/Argentina/diesel_prices/ ; Исходный источник: GlobalPetrolPrices (страновые значения только там, где они были явно помечены как страновые); Jet/мазут: н/д | AF7: Массовые оценки/медианы удалены в ходе аудита. Сохранившиеся исходные числовые значения не считаются подтверждёнными автоматически; требуется первичная проверка источника. Обновление 16.09.2026: Потребление и доли: EIA, petroleum and other liquids, 2024; включает биотопливо. Jet/мазут: национальные сопоставимые цены не найдены; исходные значения сохранены. | AG7: Бензин: проверено GPP; Дизель: проверено GPP; LPG: н/д; Jet/керосин: нет сопоставимой национальной цены; Мазут: нет сопоставимой национальной цены | AH7: AR | AI7: ARG | AJ7: ='Сводка НПЗ'!D7 -> 10 | AK7: =IF('Сводка НПЗ'!F7>0,'Сводка НПЗ'!E7,"") -> 615575 | AL7: ='Сводка НПЗ'!G7 -> 0 | AM7: 2019-02-18 | AN7: Мощность: вторичная публикация EI; число НПЗ не подтверждено | AO7: 2024 | AP7: 2025 | AQ7: 2025 | AR7: 2026-09-16
A8: 7 | B8: Dhekelia Cantonment | C8: Декелия | D8: н/д | E8: н/д | F8: =IF(AND(ISNUMBER(D8),ISNUMBER(E8)),D8*(DATE(E8+1,1,1)-DATE(E8,1,1))/1000000,"н/д") -> н/д | G8: н/д | H8: н/д | I8: н/д | J8: н/д | K8: н/д | L8: н/д | M8: н/д | N8: н/д | O8: н/д | P8: н/д | Q8: н/д | R8: н/д | S8: н/д | T8: н/д | U8: н/д | V8: н/д | W8: н/д | X8: н/д | Y8: н/д | Z8: н/д | AA8: бензин/дизель/LPG/Jet: USD/л; мазут: USD/т | AB8: бензин: 2026-09-14; дизель/LPG: 2026-09-07; Jet/мазут: н/д | AC8: https://www.jodidata.org/oil/database/data-downloads.aspx ; https://www.jodidata.org/oil/database/data-downloads.aspx | AD8: https://data.worldbank.org/ | AE8: GlobalPetrolPrices (страновые значения только там, где они были явно помечены как страновые); Jet/мазут: н/д | AF8: Массовые оценки/медианы удалены в ходе аудита. Сохранившиеся исходные числовые значения не считаются подтверждёнными автоматически; требуется первичная проверка источника. Обновление 16.09.2026: Потребление и доли: исходные значения, свежая сопоставимая серия не найдена. Jet/мазут: национальные сопоставимые цены не найдены; исходные значения сохранены. | AG8: Бензин: н/д; Дизель: н/д; LPG: н/д; Jet/керосин: нет сопоставимой национальной цены; Мазут: нет сопоставимой национальной цены | AH8: н/д | AI8: н/д | AJ8: ='Сводка НПЗ'!D8 -> 0 | AK8: =IF('Сводка НПЗ'!F8>0,'Сводка НПЗ'!E8,"") | AL8: ='Сводка НПЗ'!G8 -> 0 | AM8: 2019-02-18 | AN8: Свежие число и мощность не подтверждены | AR8: 2026-09-16
A9: 8 | B9: Cyprus | C9: Кипр | D9: 48869.041 | E9: 2025 | F9: =IF(AND(ISNUMBER(D9),ISNUMBER(E9)),D9*(DATE(E9+1,1,1)-DATE(E9,1,1))/1000000,"н/д") -> 17.8372 | G9: 32.566771 | H9: 16.440361 | I9: 3.7068598 | J9: н/д | K9: 26.346624 | L9: 0 | M9: 2025 | N9: 0 | O9: 0 | P9: 41.225787 | Q9: 2025 | R9: 3.7732535 | S9: 2025 | T9: 0.12652885 | U9: 2025 | V9: 1.907 | W9: 2.213 | X9: н/д | Y9: н/д | Z9: н/д | AA9: Бензин/дизель/LPG: USD/л; Jet/мазут: исходные единицы | AB9: Бензин: 2026-09-14; Дизель: 2026-09-14; исходные даты для непроверенных значений: бензин: 2026-09-14; дизель/LPG: 2026-09-07; Jet/мазут: н/д | AC9: https://api.eia.gov/v2/international/data/?frequency=annual&facets[productId][]=53&facets[activityId][]=1&facets[unit][]=TBPD ; https://api.eia.gov/v2/international/data/?frequency=annual&facets[productId][]=57&facets[activityId][]=1&facets[unit][]=TBPD ; https://api.eia.gov/v2/international/data/?frequency=annual&facets[productId][]=58&facets[activityId][]=1&facets[unit][]=TBPD ; https://www.jodidata.org/_resources/files/downloads/oil-data/annual-csv/secondary/2025.csv ; Исходный источник: https://www.jodidata.org/oil/database/data-downloads.aspx ; https://www.worldometers.info/oil/cyprus-oil/ | AD9: https://api.worldbank.org/v2/country/CYP/indicator/NY.GDP.MKTP.CD?format=json ; https://api.worldbank.org/v2/country/CYP/indicator/NY.GDP.MKTP.KD.ZG?format=json ; https://api.worldbank.org/v2/country/CYP/indicator/FP.CPI.TOTL.ZG?format=json ; Исходный источник: https://data.worldbank.org/ | AE9: https://www.globalpetrolprices.com/Cyprus/gasoline_prices/ ; https://www.globalpetrolprices.com/Cyprus/diesel_prices/ ; Исходный источник: GlobalPetrolPrices (страновые значения только там, где они были явно помечены как страновые); Jet/мазут: н/д | AF9: Массовые оценки/медианы удалены в ходе аудита. Сохранившиеся исходные числовые значения не считаются подтверждёнными автоматически; требуется первичная проверка источника. Обновление 16.09.2026: Потребление и доли: JODI, нефтепродукты TOTPRODS, 12 месяцев 2025. Jet/мазут: национальные сопоставимые цены не найдены; исходные значения сохранены. | AG9: Бензин: проверено GPP; Дизель: проверено GPP; LPG: н/д; Jet/керосин: нет сопоставимой национальной цены; Мазут: нет сопоставимой национальной цены | AH9: CY | AI9: CYP | AJ9: ='Сводка НПЗ'!D9 -> 0 | AK9: =IF('Сводка НПЗ'!F9>0,'Сводка НПЗ'!E9,"") | AL9: ='Сводка НПЗ'!G9 -> 0 | AM9: 2019-02-18 | AN9: Свежие число и мощность не подтверждены | AO9: 2025 | AP9: 2025 | AQ9: 2025 | AR9: 2026-09-16
A10: 9 | B10: India | C10: Индия | D10: 5477539.7 | E10: 2025 | F10: =IF(AND(ISNUMBER(D10),ISNUMBER(E10)),D10*(DATE(E10+1,1,1)-DATE(E10,1,1))/1000000,"н/д") -> 1999.302 | G10: 35.2424 | H10: 17.732723 | I10: 19.236856 | J10: 7.3199116 | K10: 2.0233017 | L10: 990278.1 | M10: 2025 | N10: 580600.35 | O10: 110560.13 | P10: 3956.0671 | Q10: 2025 | R10: 7.5666618 | S10: 2025 | T10: 2.3988495 | U10: 2025 | V10: 1.132 | W10: 1.022 | X10: н/д | Y10: 0.68 | Z10: н/д | AA10: Бензин/дизель/LPG: USD/л; Jet/мазут: исходные единицы | AB10: Бензин: 2026-09-14; Дизель: 2026-09-14; LPG: 2026-09-14; исходные даты для непроверенных значений: бензин: 2026-09-14; дизель/LPG: 2026-09-07; Jet/мазут: н/д | AC10: https://api.eia.gov/v2/international/data/?frequency=annual&facets[productId][]=53&facets[activityId][]=1&facets[unit][]=TBPD ; https://api.eia.gov/v2/international/data/?frequency=annual&facets[productId][]=57&facets[activityId][]=1&facets[unit][]=TBPD ; https://api.eia.gov/v2/international/data/?frequency=annual&facets[productId][]=58&facets[activityId][]=1&facets[unit][]=TBPD ; https://www.jodidata.org/_resources/files/downloads/oil-data/annual-csv/secondary/2025.csv ; Исходный источник: https://www.jodidata.org/oil/database/data-downloads.aspx ; https://www.worldometers.info/oil/india-oil/ | AD10: https://api.worldbank.org/v2/country/IND/indicator/NY.GDP.MKTP.CD?format=json ; https://api.worldbank.org/v2/country/IND/indicator/NY.GDP.MKTP.KD.ZG?format=json ; https://api.worldbank.org/v2/country/IND/indicator/FP.CPI.TOTL.ZG?format=json ; Исходный источник: https://data.worldbank.org/ | AE10: https://www.globalpetrolprices.com/India/gasoline_prices/ ; https://www.globalpetrolprices.com/India/diesel_prices/ ; https://www.globalpetrolprices.com/India/lpg_prices/ ; Исходный источник: GlobalPetrolPrices (страновые значения только там, где они были явно помечены как страновые); Jet/мазут: н/д | AF10: Массовые оценки/медианы удалены в ходе аудита. Сохранившиеся исходные числовые значения не считаются подтверждёнными автоматически; требуется первичная проверка источника. Обновление 16.09.2026: Потребление и доли: JODI, нефтепродукты TOTPRODS, 12 месяцев 2025. Jet/мазут: национальные сопоставимые цены не найдены; исходные значения сохранены. | AG10: Бензин: проверено GPP; Дизель: проверено GPP; LPG: проверено GPP; Jet/керосин: нет сопоставимой национальной цены; Мазут: нет сопоставимой национальной цены | AH10: IN | AI10: IND | AJ10: ='Сводка НПЗ'!D10 -> 17 | AK10: =IF('Сводка НПЗ'!F10>0,'Сводка НПЗ'!E10,"") -> 2385000 | AL10: ='Сводка НПЗ'!G10 -> 0 | AM10: 2019-02-18 | AN10: Проверен первичный источник; см. охват | AO10: 2025 | AP10: 2025 | AQ10: 2025 | AR10: 2026-09-16
A11: 10 | B11: People's Republic of China | C11: Китайская Народная Республика | D11: 16639725 | E11: 2025 | F11: =IF(AND(ISNUMBER(D11),ISNUMBER(E11)),D11*(DATE(E11+1,1,1)-DATE(E11,1,1))/1000000,"н/д") -> 6073.4995 | G11: 22.978391 | H11: 20.525819 | I11: 16.657754 | J11: н/д | K11: 4.8810399 | L11: 5446188.7 | M11: 2025 | N11: 4324684.9 | O11: 10000 | P11: 19498.039 | Q11: 2025 | R11: 4.9599489 | S11: 2025 | T11: 0.059564692 | U11: 2025 | V11: 1.326 | W11: 1.187 | X11: н/д | Y11: н/д | Z11: н/д | AA11: Бензин/дизель/LPG: USD/л; Jet/мазут: исходные единицы | AB11: Бензин: 2026-09-14; Дизель: 2026-09-14; исходные даты для непроверенных значений: бензин: 2026-09-14; дизель/LPG: 2026-09-07; Jet/мазут: н/д | AC11: https://api.eia.gov/v2/international/data/?frequency=annual&facets[productId][]=53&facets[activityId][]=1&facets[unit][]=TBPD ; https://api.eia.gov/v2/international/data/?frequency=annual&facets[productId][]=57&facets[activityId][]=1&facets[unit][]=TBPD ; https://api.eia.gov/v2/international/data/?frequency=annual&facets[productId][]=58&facets[activityId][]=1&facets[unit][]=TBPD ; https://www.jodidata.org/_resources/files/downloads/oil-data/annual-csv/secondary/2025.csv ; Исходный источник: https://www.jodidata.org/oil/database/data-downloads.aspx ; https://www.worldometers.info/oil/china-oil/ | AD11: https://api.worldbank.org/v2/country/CHN/indicator/NY.GDP.MKTP.CD?format=json ; https://api.worldbank.org/v2/country/CHN/indicator/NY.GDP.MKTP.KD.ZG?format=json ; https://api.worldbank.org/v2/country/CHN/indicator/FP.CPI.TOTL.ZG?format=json ; Исходный источник: https://data.worldbank.org/ | AE11: https://www.globalpetrolprices.com/China/gasoline_prices/ ; https://www.globalpetrolprices.com/China/diesel_prices/ ; Исходный источник: GlobalPetrolPrices (страновые значения только там, где они были явно помечены как страновые); Jet/мазут: н/д | AF11: Массовые оценки/медианы удалены в ходе аудита. Сохранившиеся исходные числовые значения не считаются подтверждёнными автоматически; требуется первичная проверка источника. Обновление 16.09.2026: Потребление и доли: JODI, нефтепродукты TOTPRODS, 12 месяцев 2025. Jet/мазут: национальные сопоставимые цены не найдены; исходные значения сохранены. | AG11: Бензин: проверено GPP; Дизель: проверено GPP; LPG: н/д; Jet/керосин: нет сопоставимой национальной цены; Мазут: нет сопоставимой национальной цены | AH11: CN | AI11: CHN | AJ11: ='Сводка НПЗ'!D11 -> 51 | AK11: =IF('Сводка НПЗ'!F11>0,'Сводка НПЗ'!E11,"") -> 5950000 | AL11: ='Сводка НПЗ'!G11 -> 0 | AM11: 2019-02-18 | AN11: Мощность: вторичная публикация EI; число НПЗ не подтверждено | AO11: 2025 | AP11: 2025 | AQ11: 2025 | AR11: 2026-09-16
A12: 11 | B12: Israel | C12: Израиль | D12: 221276.71 | E12: 2025 | F12: =IF(AND(ISNUMBER(D12),ISNUMBER(E12)),D12*(DATE(E12+1,1,1)-DATE(E12,1,1))/1000000,"н/д") -> 80.766 | G12: 27.973405 | H12: 33.947453 | I12: 6.3974938 | J12: 10.113167 | K12: 3.0978384 | L12: 25214.808 | M12: 2025 | N12: 19520.548 | O12: 0 | P12: 610.77784 | Q12: 2025 | R12: 2.9311497 | S12: 2025 | T12: 3.0414132 | U12: 2025 | V12: 2.632 | W12: 2.501 | X12: н/д | Y12: 1.088 | Z12: н/д | AA12: Бензин/дизель/LPG: USD/л; Jet/мазут: исходные единицы | AB12: Бензин: 2026-09-14; Дизель: 2026-09-14; LPG: 2026-09-14; исходные даты для непроверенных значений: бензин: 2026-09-14; дизель/LPG: 2026-09-07; Jet/мазут: н/д | AC12: https://api.eia.gov/v2/international/data/?frequency=annual&facets[productId][]=53&facets[activityId][]=1&facets[unit][]=TBPD ; https://api.eia.gov/v2/international/data/?frequency=annual&facets[productId][]=57&facets[activityId][]=1&facets[unit][]=TBPD ; https://api.eia.gov/v2/international/data/?frequency=annual&facets[productId][]=58&facets[activityId][]=1&facets[unit][]=TBPD ; https://api.eia.gov/v2/international/data/?frequency=annual&facets[productId][]=5&facets[activityId][]=2&facets[unit][]=TBPD ; Исходный источник: https://www.jodidata.org/oil/database/data-downloads.aspx ; https://www.worldometers.info/oil/israel-oil/ | AD12: https://api.worldbank.org/v2/country/ISR/indicator/NY.GDP.MKTP.CD?format=json ; https://api.worldbank.org/v2/country/ISR/indicator/NY.GDP.MKTP.KD.ZG?format=json ; https://api.worldbank.org/v2/country/ISR/indicator/FP.CPI.TOTL.ZG?format=json ; Исходный источник: https://data.worldbank.org/ | AE12: https://www.globalpetrolprices.com/Israel/gasoline_prices/ ; https://www.globalpetrolprices.com/Israel/diesel_prices/ ; https://www.globalpetrolprices.com/Israel/lpg_prices/ ; Исходный источник: GlobalPetrolPrices (страновые значения только там, где они были явно помечены как страновые); Jet/мазут: н/д | AF12: Массовые оценки/медианы удалены в ходе аудита. Сохранившиеся исходные числовые значения не считаются подтверждёнными автоматически; требуется первичная проверка источника. Обновление 16.09.2026: Потребление и доли: EIA, petroleum and other liquids, 2025; включает биотопливо. Jet/мазут: национальные сопоставимые цены не найдены; исходные значения сохранены. | AG12: Бензин: проверено GPP; Дизель: проверено GPP; LPG: проверено GPP; Jet/керосин: нет сопоставимой национальной цены; Мазут: нет сопоставимой национальной цены | AH12: IL | AI12: ISR | AJ12: ='Сводка НПЗ'!D12 -> 2 | AK12: =IF('Сводка НПЗ'!F12>0,'Сводка НПЗ'!E12,"") -> 240000 | AL12: ='Сводка НПЗ'!G12 -> 0 | AM12: 2019-02-18 | AN12: Мощность: вторичная публикация EI; число НПЗ не подтверждено | AO12: 2025 | AP12: 2025 | AQ12: 2025 | AR12: 2026-09-16
A13: 12 | B13: Palestine | C13: Палестина | D13: 34404.856 | E13: 2024 | F13: =IF(AND(ISNUMBER(D13),ISNUMBER(E13)),D13*(DATE(E13+1,1,1)-DATE(E13,1,1))/1000000,"н/д") -> 12.592177 | G13: 55.684153 | H13: 21.772048 | I13: 21.623253 | J13: 0.11518522 | K13: 0.14510722 | L13: 0 | M13: 2025 | N13: 0 | O13: 0 | P13: 17.1671 | Q13: 2025 | R13: 4.3444407 | S13: 2025 | T13: 9.8084012 | U13: 2025 | V13: н/д | W13: н/д | X13: н/д | Y13: н/д | Z13: н/д | AA13: бензин/дизель/LPG/Jet: USD/л; мазут: USD/т | AB13: бензин: 2026-09-14; дизель/LPG: 2026-09-07; Jet/мазут: н/д | AC13: https://api.eia.gov/v2/international/data/?frequency=annual&facets[productId][]=53&facets[activityId][]=1&facets[unit][]=TBPD ; https://api.eia.gov/v2/international/data/?frequency=annual&facets[productId][]=57&facets[activityId][]=1&facets[unit][]=TBPD ; https://api.eia.gov/v2/international/data/?frequency=annual&facets[productId][]=58&facets[activityId][]=1&facets[unit][]=TBPD ; https://api.eia.gov/v2/international/data/?frequency=annual&facets[productId][]=5&facets[activityId][]=2&facets[unit][]=TBPD ; Исходный источник: https://www.jodidata.org/oil/database/data-downloads.aspx ; https://www.worldometers.info/oil/state-of-palestine-oil/ | AD13: https://api.worldbank.org/v2/country/PSE/indicator/NY.GDP.MKTP.CD?format=json ; https://api.worldbank.org/v2/country/PSE/indicator/NY.GDP.MKTP.KD.ZG?format=json ; https://api.worldbank.org/v2/country/PSE/indicator/FP.CPI.TOTL.ZG?format=json ; Исходный источник: https://data.worldbank.org/ | AE13: GlobalPetrolPrices (страновые значения только там, где они были явно помечены как страновые); Jet/мазут: н/д | AF13: Массовые оценки/медианы удалены в ходе аудита. Сохранившиеся исходные числовые значения не считаются подтверждёнными автоматически; требуется первичная проверка источника. Обновление 16.09.2026: Потребление и доли: EIA, petroleum and other liquids, 2024; включает биотопливо. Jet/мазут: национальные сопоставимые цены не найдены; исходные значения сохранены. | AG13: Бензин: н/д; Дизель: н/д; LPG: н/д; Jet/керосин: нет сопоставимой национальной цены; Мазут: нет сопоставимой национальной цены | AH13: PS | AI13: PSE | AJ13: ='Сводка НПЗ'!D13 -> 0 | AK13: =IF('Сводка НПЗ'!F13>0,'Сводка НПЗ'!E13,"") | AL13: ='Сводка НПЗ'!G13 -> 0 | AM13: 2019-02-18 | AN13: Свежие число и мощность не подтверждены | AO13: 2024 | AP13: 2025 | AQ13: 2025 | AR13: 2026-09-16
A14: 13 | B14: Lebanon | C14: Ливан | D14: 114321.37 | E14: 2024 | F14: =IF(AND(ISNUMBER(D14),ISNUMBER(E14)),D14*(DATE(E14+1,1,1)-DATE(E14,1,1))/1000000,"н/д") -> 41.84162 | G14: 52.18751 | H14: 34.55931 | I14: 6.2332578 | J14: 3.6447105 | K14: 3.0353295 | L14: 0 | M14: 2025 | N14: 0 | O14: 0 | P14: 25.971643 | Q14: 2024 | R14: -7.0798919 | S14: 2024 | T14: 14.597596 | U14: 2025 | V14: 1.38 | W14: 1.341 | X14: н/д | Y14: 0.62 | Z14: н/д | AA14: Бензин/дизель/LPG: USD/л; Jet/мазут: исходные единицы | AB14: Бензин: 2026-09-14; Дизель: 2026-09-14; LPG: 2026-09-14; исходные даты для непроверенных значений: бензин: 2026-09-14; дизель/LPG: 2026-09-07; Jet/мазут: н/д | AC14: https://api.eia.gov/v2/international/data/?frequency=annual&facets[productId][]=53&facets[activityId][]=1&facets[unit][]=TBPD ; https://api.eia.gov/v2/international/data/?frequency=annual&facets[productId][]=57&facets[activityId][]=1&facets[unit][]=TBPD ; https://api.eia.gov/v2/international/data/?frequency=annual&facets[productId][]=58&facets[activityId][]=1&facets[unit][]=TBPD ; https://api.eia.gov/v2/international/data/?frequency=annual&facets[productId][]=5&facets[activityId][]=2&facets[unit][]=TBPD ; Исходный источник: https://www.jodidata.org/oil/database/data-downloads.aspx ; https://www.worldometers.info/oil/lebanon-oil/ | AD14: https://api.worldbank.org/v2/country/LBN/indicator/NY.GDP.MKTP.CD?format=json ; https://api.worldbank.org/v2/country/LBN/indicator/NY.GDP.MKTP.KD.ZG?format=json ; https://api.worldbank.org/v2/country/LBN/indicator/FP.CPI.TOTL.ZG?format=json ; Исходный источник: https://data.worldbank.org/ | AE14: https://www.globalpetrolprices.com/Lebanon/gasoline_prices/ ; https://www.globalpetrolprices.com/Lebanon/diesel_prices/ ; https://www.globalpetrolprices.com/Lebanon/lpg_prices/ ; Исходный источник: GlobalPetrolPrices (страновые значения только там, где они были явно помечены как страновые); Jet/мазут: н/д | AF14: Массовые оценки/медианы удалены в ходе аудита. Сохранившиеся исходные числовые значения не считаются подтверждёнными автоматически; требуется первичная проверка источника. Обновление 16.09.2026: Потребление и доли: EIA, petroleum and other liquids, 2024; включает биотопливо. Jet/мазут: национальные сопоставимые цены не найдены; исходные значения сохранены. | AG14: Бензин: проверено GPP; Дизель: проверено GPP; LPG: проверено GPP; Jet/керосин: нет сопоставимой национальной цены; Мазут: нет сопоставимой национальной цены | AH14: LB | AI14: LBN | AJ14: ='Сводка НПЗ'!D14 -> 0 | AK14: =IF('Сводка НПЗ'!F14>0,'Сводка НПЗ'!E14,"") | AL14: ='Сводка НПЗ'!G14 -> 0 | AM14: 2019-02-18 | AN14: Свежие число и мощность не подтверждены | AO14: 2024 | AP14: 2025 | AQ14: 2025 | AR14: 2026-09-16
A15: 14 | B15: Ethiopia | C15: Эфиопия | D15: 103689.34 | E15: 2024 | F15: =IF(AND(ISNUMBER(D15),ISNUMBER(E15)),D15*(DATE(E15+1,1,1)-DATE(E15,1,1))/1000000,"н/д") -> 37.950298 | G15: 48.396516 | H15: 16.638355 | I15: 0.3138225 | J15: 26.344966 | K15: 1.2432241 | L15: 0 | M15: 2025 | N15: 0 | O15: 0 | P15: 126.35876 | Q15: 2025 | R15: 9.7715182 | S15: 2025 | T15: 13.229643 | U15: 2025 | V15: 1.027 | W15: 1.106 | X15: н/д | Y15: н/д | Z15: н/д | AA15: Бензин/дизель/LPG: USD/л; Jet/мазут: исходные единицы | AB15: Бензин: 2026-09-14; Дизель: 2026-09-14; исходные даты для непроверенных значений: бензин: 2026-09-14; дизель/LPG: 2026-09-07; Jet/мазут: н/д | AC15: https://api.eia.gov/v2/international/data/?frequency=annual&facets[productId][]=53&facets[activityId][]=1&facets[unit][]=TBPD ; https://api.eia.gov/v2/international/data/?frequency=annual&facets[productId][]=57&facets[activityId][]=1&facets[unit][]=TBPD ; https://api.eia.gov/v2/international/data/?frequency=annual&facets[productId][]=58&facets[activityId][]=1&facets[unit][]=TBPD ; https://api.eia.gov/v2/international/data/?frequency=annual&facets[productId][]=5&facets[activityId][]=2&facets[unit][]=TBPD ; Исходный источник: https://www.jodidata.org/oil/database/data-downloads.aspx ; https://www.worldometers.info/oil/ethiopia-oil/ | AD15: https://api.worldbank.org/v2/country/ETH/indicator/NY.GDP.MKTP.CD?format=json ; https://api.worldbank.org/v2/country/ETH/indicator/NY.GDP.MKTP.KD.ZG?format=json ; https://api.worldbank.org/v2/country/ETH/indicator/FP.CPI.TOTL.ZG?format=json ; Исходный источник: https://data.worldbank.org/ | AE15: https://www.globalpetrolprices.com/Ethiopia/gasoline_prices/ ; https://www.globalpetrolprices.com/Ethiopia/diesel_prices/ ; Исходный источник: GlobalPetrolPrices (страновые значения только там, где они были явно помечены как страновые); Jet/мазут: н/д | AF15: Массовые оценки/медианы удалены в ходе аудита. Сохранившиеся исходные числовые значения не считаются подтверждёнными автоматически; требуется первичная проверка источника. Обновление 16.09.2026: Потребление и доли: EIA, petroleum and other liquids, 2024; включает биотопливо. Jet/мазут: национальные сопоставимые цены не найдены; исходные значения сохранены. | AG15: Бензин: проверено GPP; Дизель: проверено GPP; LPG: н/д; Jet/керосин: нет сопоставимой национальной цены; Мазут: нет сопоставимой национальной цены | AH15: ET | AI15: ETH | AJ15: ='Сводка НПЗ'!D15 -> 0 | AK15: =IF('Сводка НПЗ'!F15>0,'Сводка НПЗ'!E15,"") | AL15: ='Сводка НПЗ'!G15 -> 0 | AM15: 2019-02-18 | AN15: Свежие число и мощность не подтверждены | AO15: 2024 | AP15: 2025 | AQ15: 2025 | AR15: 2026-09-16
A16: 15 | B16: South Sudan | C16: Южный Судан | D16: 11889.538 | E16: 2024 | F16: =IF(AND(ISNUMBER(D16),ISNUMBER(E16)),D16*(DATE(E16+1,1,1)-DATE(E16,1,1))/1000000,"н/д") -> 4.351571 | G16: 74.536213 | H16: 9.4696737 | I16: 0.82199162 | J16: 15.172122 | K16: 0 | L16: 112657.53 | M16: 2025 | N16: 112657.53 | O16: 0 | P16: 12 | Q16: 2024 | R16: -10.8 | S16: 2024 | T16: 91.440822 | U16: 2024 | V16: н/д | W16: н/д | X16: н/д | Y16: н/д | Z16: н/д | AA16: бензин/дизель/LPG/Jet: USD/л; мазут: USD/т | AB16: бензин: 2026-09-14; дизель/LPG: 2026-09-07; Jet/мазут: н/д | AC16: https://api.eia.gov/v2/international/data/?frequency=annual&facets[productId][]=53&facets[activityId][]=1&facets[unit][]=TBPD ; https://api.eia.gov/v2/international/data/?frequency=annual&facets[productId][]=57&facets[activityId][]=1&facets[unit][]=TBPD ; https://api.eia.gov/v2/international/data/?frequency=annual&facets[productId][]=58&facets[activityId][]=1&facets[unit][]=TBPD ; https://api.eia.gov/v2/international/data/?frequency=annual&facets[productId][]=5&facets[activityId][]=2&facets[unit][]=TBPD ; Исходный источник: https://www.jodidata.org/oil/database/data-downloads.aspx ; https://www.worldometers.info/oil/south-sudan-oil/ | AD16: https://api.worldbank.org/v2/country/SSD/indicator/NY.GDP.MKTP.CD?format=json ; https://api.worldbank.org/v2/country/SSD/indicator/NY.GDP.MKTP.KD.ZG?format=json ; https://api.worldbank.org/v2/country/SSD/indicator/FP.CPI.TOTL.ZG?format=json ; Исходный источник: https://data.worldbank.org/ | AE16: GlobalPetrolPrices (страновые значения только там, где они были явно помечены как страновые); Jet/мазут: н/д | AF16: Массовые оценки/медианы удалены в ходе аудита. Сохранившиеся исходные числовые значения не считаются подтверждёнными автоматически; требуется первичная проверка источника. Обновление 16.09.2026: Потребление и доли: EIA, petroleum and other liquids, 2024; включает биотопливо. Jet/мазут: национальные сопоставимые цены не найдены; исходные значения сохранены. | AG16: Бензин: н/д; Дизель: н/д; LPG: н/д; Jet/керосин: нет сопоставимой национальной цены; Мазут: нет сопоставимой национальной цены | AH16: SS | AI16: SSD | AJ16: ='Сводка НПЗ'!D16 -> 0 | AK16: =IF('Сводка НПЗ'!F16>0,'Сводка НПЗ'!E16,"") | AL16: ='Сводка НПЗ'!G16 -> 0 | AM16: 2019-02-18 | AN16: Свежие число и мощность не подтверждены | AO16: 2024 | AP16: 2025 | AQ16: 2025 | AR16: 2026-09-16
A17: 16 | B17: Somalia | C17: Сомали | D17: 11150.205 | E17: 2024 | F17: =IF(AND(ISNUMBER(D17),ISNUMBER(E17)),D17*(DATE(E17+1,1,1)-DATE(E17,1,1))/1000000,"н/д") -> 4.0809749 | G17: 34.96256 | H17: 19.602187 | I17: 3.3576896 | J17: 36.22718 | K17: 5.850384 | L17: 0 | M17: 2025 | N17: 0 | O17: 0 | P17: 12.9952 | Q17: 2025 | R17: 2.991144 | S17: 2025 | T17: н/д | U17: н/д | V17: н/д | W17: н/д | X17: н/д | Y17: н/д | Z17: н/д | AA17: бензин/дизель/LPG/Jet: USD/л; мазут: USD/т | AB17: бензин: 2026-09-14; дизель/LPG: 2026-09-07; Jet/мазут: н/д | AC17: https://api.eia.gov/v2/international/data/?frequency=annual&facets[productId][]=53&facets[activityId][]=1&facets[unit][]=TBPD ; https://api.eia.gov/v2/international/data/?frequency=annual&facets[productId][]=57&facets[activityId][]=1&facets[unit][]=TBPD ; https://api.eia.gov/v2/international/data/?frequency=annual&facets[productId][]=58&facets[activityId][]=1&facets[unit][]=TBPD ; https://api.eia.gov/v2/international/data/?frequency=annual&facets[productId][]=5&facets[activityId][]=2&facets[unit][]=TBPD ; Исходный источник: https://www.jodidata.org/oil/database/data-downloads.aspx ; https://www.worldometers.info/oil/somalia-oil/ | AD17: https://api.worldbank.org/v2/country/SOM/indicator/NY.GDP.MKTP.CD?format=json ; https://api.worldbank.org/v2/country/SOM/indicator/NY.GDP.MKTP.KD.ZG?format=json ; https://api.worldbank.org/v2/country/SOM/indicator/FP.CPI.TOTL.ZG?format=json ; Исходный источник: https://data.worldbank.org/ | AE17: GlobalPetrolPrices (страновые значения только там, где они были явно помечены как страновые); Jet/мазут: н/д | AF17: Массовые оценки/медианы удалены в ходе аудита. Сохранившиеся исходные числовые значения не считаются подтверждёнными автоматически; требуется первичная проверка источника. Обновление 16.09.2026: Потребление и доли: EIA, petroleum and other liquids, 2024; включает биотопливо. Jet/мазут: национальные сопоставимые цены не найдены; исходные значения сохранены. | AG17: Бензин: н/д; Дизель: н/д; LPG: н/д; Jet/керосин: нет сопоставимой национальной цены; Мазут: нет сопоставимой национальной цены | AH17: SO | AI17: SOM | AJ17: ='Сводка НПЗ'!D17 -> 0 | AK17: =IF('Сводка НПЗ'!F17>0,'Сводка НПЗ'!E17,"") | AL17: ='Сводка НПЗ'!G17 -> 0 | AM17: 2019-02-18 | AN17: Свежие число и мощность не подтверждены | AO17: 2024 | AP17: 2025 | AQ17: 2025 | AR17: 2026-09-16
A18: 17 | B18: Kenya | C18: Кения | D18: 116161.21 | E18: 2024 | F18: =IF(AND(ISNUMBER(D18),ISNUMBER(E18)),D18*(DATE(E18+1,1,1)-DATE(E18,1,1))/1000000,"н/д") -> 42.515001 | G18: 38.902149 | H18: 29.855817 | I18: 11.354084 | J18: 14.43898 | K18: 3.8170384 | L18: 0 | M18: 2025 | N18: 0 | O18: 0 | P18: 135.94128 | Q18: 2025 | R18: 4.6326109 | S18: 2025 | T18: 4.0691288 | U18: 2025 | V18: 1.642 | W18: 1.673 | X18: н/д | Y18: н/д | Z18: н/д | AA18: Бензин/дизель/LPG: USD/л; Jet/мазут: исходные единицы | AB18: Бензин: 2026-09-14; Дизель: 2026-09-14; исходные даты для непроверенных значений: бензин: 2026-09-14; дизель/LPG: 2026-09-07; Jet/мазут: н/д | AC18: https://api.eia.gov/v2/international/data/?frequency=annual&facets[productId][]=53&facets[activityId][]=1&facets[unit][]=TBPD ; https://api.eia.gov/v2/international/data/?frequency=annual&facets[productId][]=57&facets[activityId][]=1&facets[unit][]=TBPD ; https://api.eia.gov/v2/international/data/?frequency=annual&facets[productId][]=58&facets[activityId][]=1&facets[unit][]=TBPD ; https://api.eia.gov/v2/international/data/?frequency=annual&facets[productId][]=5&facets[activityId][]=2&facets[unit][]=TBPD ; Исходный источник: https://www.jodidata.org/oil/database/data-downloads.aspx ; https://www.worldometers.info/oil/kenya-oil/ | AD18: https://api.worldbank.org/v2/country/KEN/indicator/NY.GDP.MKTP.CD?format=json ; https://api.worldbank.org/v2/country/KEN/indicator/NY.GDP.MKTP.KD.ZG?format=json ; https://api.worldbank.org/v2/country/KEN/indicator/FP.CPI.TOTL.ZG?format=json ; Исходный источник: https://data.worldbank.org/ | AE18: https://www.globalpetrolprices.com/Kenya/gasoline_prices/ ; https://www.globalpetrolprices.com/Kenya/diesel_prices/ ; Исходный источник: GlobalPetrolPrices (страновые значения только там, где они были явно помечены как страновые); Jet/мазут: н/д | AF18: Массовые оценки/медианы удалены в ходе аудита. Сохранившиеся исходные числовые значения не считаются подтверждёнными автоматически; требуется первичная проверка источника. Обновление 16.09.2026: Потребление и доли: EIA, petroleum and other liquids, 2024; включает биотопливо. Jet/мазут: национальные сопоставимые цены не найдены; исходные значения сохранены. | AG18: Бензин: проверено GPP; Дизель: проверено GPP; LPG: н/д; Jet/керосин: нет сопоставимой национальной цены; Мазут: нет сопоставимой национальной цены | AH18: KE | AI18: KEN | AJ18: ='Сводка НПЗ'!D18 -> 1 | AK18: =IF('Сводка НПЗ'!F18>0,'Сводка НПЗ'!E18,"") -> 90000 | AL18: ='Сводка НПЗ'!G18 -> 0 | AM18: 2019-02-18 | AN18: Свежие число и мощность не подтверждены | AO18: 2024 | AP18: 2025 | AQ18: 2025 | AR18: 2026-09-16
A19: 18 | B19: Malawi | C19: Малави | D19: 10525.095 | E19: 2024 | F19: =IF(AND(ISNUMBER(D19),ISNUMBER(E19)),D19*(DATE(E19+1,1,1)-DATE(E19,1,1))/1000000,"н/д") -> 3.8521846 | G19: 48.585008 | H19: 45.723156 | I19: 0.621792 | J19: 1.0201678 | K19: 0.44624301 | L19: 0 | M19: 2025 | N19: 0 | O19: 0 | P19: 14.918277 | Q19: 2025 | R19: 1.8851871 | S19: 2025 | T19: 28.370257 | U19: 2025 | V19: 3.242 | W19: 3.383 | X19: н/д | Y19: н/д | Z19: н/д | AA19: Бензин/дизель/LPG: USD/л; Jet/мазут: исходные единицы | AB19: Бензин: 2026-09-14; Дизель: 2026-09-14; исходные даты для непроверенных значений: бензин: 2026-09-14; дизель/LPG: 2026-09-07; Jet/мазут: н/д | AC19: https://api.eia.gov/v2/international/data/?frequency=annual&facets[productId][]=53&facets[activityId][]=1&facets[unit][]=TBPD ; https://api.eia.gov/v2/international/data/?frequency=annual&facets[productId][]=57&facets[activityId][]=1&facets[unit][]=TBPD ; https://api.eia.gov/v2/international/data/?frequency=annual&facets[productId][]=58&facets[activityId][]=1&facets[unit][]=TBPD ; https://api.eia.gov/v2/international/data/?frequency=annual&facets[productId][]=5&facets[activityId][]=2&facets[unit][]=TBPD ; Исходный источник: https://www.jodidata.org/oil/database/data-downloads.aspx ; https://www.worldometers.info/oil/malawi-oil/ | AD19: https://api.worldbank.org/v2/country/MWI/indicator/NY.GDP.MKTP.CD?format=json ; https://api.worldbank.org/v2/country/MWI/indicator/NY.GDP.MKTP.KD.ZG?format=json ; https://api.worldbank.org/v2/country/MWI/indicator/FP.CPI.TOTL.ZG?format=json ; Исходный источник: https://data.worldbank.org/ | AE19: https://www.globalpetrolprices.com/Malawi/gasoline_prices/ ; https://www.globalpetrolprices.com/Malawi/diesel_prices/ ; Исходный источник: GlobalPetrolPrices (страновые значения только там, где они были явно помечены как страновые); Jet/мазут: н/д | AF19: Массовые оценки/медианы удалены в ходе аудита. Сохранившиеся исходные числовые значения не считаются подтверждёнными автоматически; требуется первичная проверка источника. Обновление 16.09.2026: Потребление и доли: EIA, petroleum and other liquids, 2024; включает биотопливо. Jet/мазут: национальные сопоставимые цены не найдены; исходные значения сохранены. | AG19: Бензин: проверено GPP; Дизель: проверено GPP; LPG: н/д; Jet/керосин: нет сопоставимой национальной цены; Мазут: нет сопоставимой национальной цены | AH19: MW | AI19: MWI | AJ19: ='Сводка НПЗ'!D19 -> 0 | AK19: =IF('Сводка НПЗ'!F19>0,'Сводка НПЗ'!E19,"") | AL19: ='Сводка НПЗ'!G19 -> 0 | AM19: 2019-02-18 | AN19: Свежие число и мощность не подтверждены | AO19: 2024 | AP19: 2025 | AQ19: 2025 | AR19: 2026-09-16
A20: 19 | B20: Tanzania | C20: Танзания | D20: 83535.87 | E20: 2024 | F20: =IF(AND(ISNUMBER(D20),ISNUMBER(E20)),D20*(DATE(E20+1,1,1)-DATE(E20,1,1))/1000000,"н/д") -> 30.574129 | G20: 46.477096 | H20: 32.906473 | I20: 14.227915 | J20: 4.743333 | K20: 1.4099548 | L20: 0 | M20: 2025 | N20: 0 | O20: 0 | P20: 90.143496 | Q20: 2025 | R20: 5.8528683 | S20: 2025 | T20: 3.3269736 | U20: 2025 | V20: 1.435 | W20: 1.465 | X20: н/д | Y20: н/д | Z20: н/д | AA20: Бензин/дизель/LPG: USD/л; Jet/мазут: исходные единицы | AB20: Бензин: 2026-09-14; Дизель: 2026-09-14; исходные даты для непроверенных значений: бензин: 2026-09-14; дизель/LPG: 2026-09-07; Jet/мазут: н/д | AC20: https://api.eia.gov/v2/international/data/?frequency=annual&facets[productId][]=53&facets[activityId][]=1&facets[unit][]=TBPD ; https://api.eia.gov/v2/international/data/?frequency=annual&facets[productId][]=57&facets[activityId][]=1&facets[unit][]=TBPD ; https://api.eia.gov/v2/international/data/?frequency=annual&facets[productId][]=58&facets[activityId][]=1&facets[unit][]=TBPD ; https://api.eia.gov/v2/international/data/?frequency=annual&facets[productId][]=5&facets[activityId][]=2&facets[unit][]=TBPD ; Исходный источник: https://www.jodidata.org/oil/database/data-downloads.aspx ; https://www.worldometers.info/oil/tanzania-oil/ | AD20: https://api.worldbank.org/v2/country/TZA/indicator/NY.GDP.MKTP.CD?format=json ; https://api.worldbank.org/v2/country/TZA/indicator/NY.GDP.MKTP.KD.ZG?format=json ; https://api.worldbank.org/v2/country/TZA/indicator/FP.CPI.TOTL.ZG?format=json ; Исходный источник: https://data.worldbank.org/ | AE20: https://www.globalpetrolprices.com/Tanzania/gasoline_prices/ ; https://www.globalpetrolprices.com/Tanzania/diesel_prices/ ; Исходный источник: GlobalPetrolPrices (страновые значения только там, где они были явно помечены как страновые); Jet/мазут: н/д | AF20: Массовые оценки/медианы удалены в ходе аудита. Сохранившиеся исходные числовые значения не считаются подтверждёнными автоматически; требуется первичная проверка источника. Обновление 16.09.2026: Потребление и доли: EIA, petroleum and other liquids, 2024; включает биотопливо. Jet/мазут: национальные сопоставимые цены не найдены; исходные значения сохранены. | AG20: Бензин: проверено GPP; Дизель: проверено GPP; LPG: н/д; Jet/керосин: нет сопоставимой национальной цены; Мазут: нет сопоставимой национальной цены | AH20: TZ | AI20: TZA | AJ20: ='Сводка НПЗ'!D20 -> 1 | AK20: =IF('Сводка НПЗ'!F20>0,'Сводка НПЗ'!E20,"") -> 14900 | AL20: ='Сводка НПЗ'!G20 -> 0 | AM20: 2019-02-18 | AN20: Свежие число и мощность не подтверждены | AO20: 2024 | AP20: 2025 | AQ20: 2025 | AR20: 2026-09-16
A21: 20 | B21: Syria | C21: Сирия | D21: 123816.55 | E21: 2024 | F21: =IF(AND(ISNUMBER(D21),ISNUMBER(E21)),D21*(DATE(E21+1,1,1)-DATE(E21,1,1))/1000000,"н/д") -> 45.316857 | G21: 29.446712 | H21: 16.730229 | I21: 11.25903 | J21: 1.3123757 | K21: 38.606684 | L21: 81234.655 | M21: 2025 | N21: 75246.575 | O21: 7690.5808 | P21: 23.62 | Q21: 2024 | R21: 0.7 | S21: 2024 | T21: 13.4 | U21: 2019 | V21: 1.299 | W21: 1.068 | X21: н/д | Y21: н/д | Z21: н/д | AA21: Бензин/дизель/LPG: USD/л; Jet/мазут: исходные единицы | AB21: Бензин: 2026-09-14; Дизель: 2026-09-14; исходные даты для непроверенных значений: бензин: 2026-09-14; дизель/LPG: 2026-09-07; Jet/мазут: н/д | AC21: https://api.eia.gov/v2/international/data/?frequency=annual&facets[productId][]=53&facets[activityId][]=1&facets[unit][]=TBPD ; https://api.eia.gov/v2/international/data/?frequency=annual&facets[productId][]=57&facets[activityId][]=1&facets[unit][]=TBPD ; https://api.eia.gov/v2/international/data/?frequency=annual&facets[productId][]=58&facets[activityId][]=1&facets[unit][]=TBPD ; https://api.eia.gov/v2/international/data/?frequency=annual&facets[productId][]=5&facets[activityId][]=2&facets[unit][]=TBPD ; Исходный источник: https://www.jodidata.org/oil/database/data-downloads.aspx ; https://www.worldometers.info/oil/syria-oil/ | AD21: https://data.worldbank.org/ | AE21: https://www.globalpetrolprices.com/Syria/gasoline_prices/ ; https://www.globalpetrolprices.com/Syria/diesel_prices/ ; Исходный источник: GlobalPetrolPrices (страновые значения только там, где они были явно помечены как страновые); Jet/мазут: н/д | AF21: Массовые оценки/медианы удалены в ходе аудита. Сохранившиеся исходные числовые значения не считаются подтверждёнными автоматически; требуется первичная проверка источника. Обновление 16.09.2026: Потребление и доли: EIA, petroleum and other liquids, 2024; включает биотопливо. Jet/мазут: национальные сопоставимые цены не найдены; исходные значения сохранены. | AG21: Бензин: проверено GPP; Дизель: проверено GPP; LPG: н/д; Jet/керосин: нет сопоставимой национальной цены; Мазут: нет сопоставимой национальной цены | AH21: SY | AI21: SYR | AJ21: ='Сводка НПЗ'!D21 -> 2 | AK21: =IF('Сводка НПЗ'!F21>0,'Сводка НПЗ'!E21,"") -> 239865 | AL21: ='Сводка НПЗ'!G21 -> 0 | AM21: 2019-02-18 | AN21: Свежие число и мощность не подтверждены | AO21: 2024 | AP21: 2025 | AQ21: 2025 | AR21: 2026-09-16
A22: 21 | B22: Somaliland | C22: Сомалиленд | D22: н/д | E22: н/д | F22: =IF(AND(ISNUMBER(D22),ISNUMBER(E22)),D22*(DATE(E22+1,1,1)-DATE(E22,1,1))/1000000,"н/д") -> н/д | G22: н/д | H22: н/д | I22: н/д | J22: н/д | K22: н/д | L22: н/д | M22: н/д | N22: н/д | O22: н/д | P22: н/д | Q22: н/д | R22: н/д | S22: н/д | T22: н/д | U22: н/д | V22: н/д | W22: н/д | X22: н/д | Y22: н/д | Z22: н/д | AA22: бензин/дизель/LPG/Jet: USD/л; мазут: USD/т | AB22: бензин: 2026-09-14; дизель/LPG: 2026-09-07; Jet/мазут: н/д | AC22: https://www.jodidata.org/oil/database/data-downloads.aspx | AD22: https://data.worldbank.org/ | AE22: GlobalPetrolPrices (страновые значения только там, где они были явно помечены как страновые); Jet/мазут: н/д | AF22: Массовые оценки/медианы удалены в ходе аудита. Сохранившиеся исходные числовые значения не считаются подтверждёнными автоматически; требуется первичная проверка источника. Обновление 16.09.2026: Потребление и доли: исходные значения, свежая сопоставимая серия не найдена. Jet/мазут: национальные сопоставимые цены не найдены; исходные значения сохранены. | AG22: Бензин: н/д; Дизель: н/д; LPG: н/д; Jet/керосин: нет сопоставимой национальной цены; Мазут: нет сопоставимой национальной цены | AH22: н/д | AI22: н/д | AJ22: ='Сводка НПЗ'!D22 -> 0 | AK22: =IF('Сводка НПЗ'!F22>0,'Сводка НПЗ'!E22,"") | AL22: ='Сводка НПЗ'!G22 -> 0 | AM22: 2019-02-18 | AN22: Свежие число и мощность не подтверждены | AR22: 2026-09-16
A23: 22 | B23: France | C23: Франция | D23: 1512298.6 | E23: 2025 | F23: =IF(AND(ISNUMBER(D23),ISNUMBER(E23)),D23*(DATE(E23+1,1,1)-DATE(E23,1,1))/1000000,"н/д") -> 551.989 | G23: 49.173462 | H23: 18.512298 | I23: 6.4389689 | J23: 22.826759 | K23: 1.519052 | L23: 105888.77 | M23: 2025 | N23: 10221.83 | O23: 0 | P23: 3366.3159 | Q23: 2025 | R23: 0.84094996 | S23: 2025 | T23: 0.94377021 | U23: 2025 | V23: 2.425 | W23: 2.664 | X23: н/д | Y23: 1.192 | Z23: н/д | AA23: Бензин/дизель/LPG: USD/л; Jet/мазут: исходные единицы | AB23: Бензин: 2026-09-14; Дизель: 2026-09-14; LPG: 2026-09-14; исходные даты для непроверенных значений: бензин: 2026-09-14; дизель/LPG: 2026-09-07; Jet/мазут: н/д | AC23: https://api.eia.gov/v2/international/data/?frequency=annual&facets[productId][]=53&facets[activityId][]=1&facets[unit][]=TBPD ; https://api.eia.gov/v2/international/data/?frequency=annual&facets[productId][]=57&facets[activityId][]=1&facets[unit][]=TBPD ; https://api.eia.gov/v2/international/data/?frequency=annual&facets[productId][]=58&facets[activityId][]=1&facets[unit][]=TBPD ; https://www.jodidata.org/_resources/files/downloads/oil-data/annual-csv/secondary/2025.csv ; Исходный источник: https://www.jodidata.org/oil/database/data-downloads.aspx ; https://www.worldometers.info/oil/france-oil/ | AD23: https://api.worldbank.org/v2/country/FRA/indicator/NY.GDP.MKTP.CD?format=json ; https://api.worldbank.org/v2/country/FRA/indicator/NY.GDP.MKTP.KD.ZG?format=json ; https://api.worldbank.org/v2/country/FRA/indicator/FP.CPI.TOTL.ZG?format=json ; Исходный источник: https://data.worldbank.org/ | AE23: https://www.globalpetrolprices.com/France/gasoline_prices/ ; https://www.globalpetrolprices.com/France/diesel_prices/ ; https://www.globalpetrolprices.com/France/lpg_prices/ ; Исходный источник: GlobalPetrolPrices (страновые значения только там, где они были явно помечены как страновые); Jet/мазут: н/д | AF23: Массовые оценки/медианы удалены в ходе аудита. Сохранившиеся исходные числовые значения не считаются подтверждёнными автоматически; требуется первичная проверка источника. Обновление 16.09.2026: Потребление и доли: JODI, нефтепродукты TOTPRODS, 12 месяцев 2025. Jet/мазут: национальные сопоставимые цены не найдены; исходные значения сохранены. | AG23: Бензин: проверено GPP; Дизель: проверено GPP; LPG: проверено GPP; Jet/керосин: нет сопоставимой национальной цены; Мазут: нет сопоставимой национальной цены | AH23: FR | AI23: FRA | AJ23: ='Сводка НПЗ'!D23 -> 14 | AK23: =IF('Сводка НПЗ'!F23>0,'Сводка НПЗ'!E23,"") -> 2075000 | AL23: ='Сводка НПЗ'!G23 -> 1 | AM23: 2019-02-18 | AN23: Проверен первичный источник; см. охват | AO23: 2025 | AP23: 2025 | AQ23: 2025 | AR23: 2026-09-16
A24: 23 | B24: Suriname | C24: Суринам | D24: 14772.43 | E24: 2024 | F24: =IF(AND(ISNUMBER(D24),ISNUMBER(E24)),D24*(DATE(E24+1,1,1)-DATE(E24,1,1))/1000000,"н/д") -> 5.4067095 | G24: 43.899514 | H24: 32.881618 | I24: 5.1844541 | J24: 6.6453751 | K24: 9.9219725 | L24: 11659.956 | M24: 2025 | N24: 12089.451 | O24: 0 | P24: 4.5236578 | Q24: 2025 | R24: 1.7916915 | S24: 2025 | T24: 9.2054682 | U24: 2025 | V24: 1.28 | W24: 1.411 | X24: н/д | Y24: н/д | Z24: н/д | AA24: Бензин/дизель/LPG: USD/л; Jet/мазут: исходные единицы | AB24: Бензин: 2026-09-14; Дизель: 2026-09-14; исходные даты для непроверенных значений: бензин: 2026-09-14; дизель/LPG: 2026-09-07; Jet/мазут: н/д | AC24: https://api.eia.gov/v2/international/data/?frequency=annual&facets[productId][]=53&facets[activityId][]=1&facets[unit][]=TBPD ; https://api.eia.gov/v2/international/data/?frequency=annual&facets[productId][]=57&facets[activityId][]=1&facets[unit][]=TBPD ; https://api.eia.gov/v2/international/data/?frequency=annual&facets[productId][]=58&facets[activityId][]=1&facets[unit][]=TBPD ; https://api.eia.gov/v2/international/data/?frequency=annual&facets[productId][]=5&facets[activityId][]=2&facets[unit][]=TBPD ; Исходный источник: https://www.jodidata.org/oil/database/data-downloads.aspx ; https://www.worldometers.info/oil/suriname-oil/ | AD24: https://api.worldbank.org/v2/country/SUR/indicator/NY.GDP.MKTP.CD?format=json ; https://api.worldbank.org/v2/country/SUR/indicator/NY.GDP.MKTP.KD.ZG?format=json ; https://api.worldbank.org/v2/country/SUR/indicator/FP.CPI.TOTL.ZG?format=json ; Исходный источник: https://data.worldbank.org/ | AE24: https://www.globalpetrolprices.com/Suriname/gasoline_prices/ ; https://www.globalpetrolprices.com/Suriname/diesel_prices/ ; Исходный источник: GlobalPetrolPrices (страновые значения только там, где они были явно помечены как страновые); Jet/мазут: н/д | AF24: Массовые оценки/медианы удалены в ходе аудита. Сохранившиеся исходные числовые значения не считаются подтверждёнными автоматически; требуется первичная проверка источника. Обновление 16.09.2026: Потребление и доли: EIA, petroleum and other liquids, 2024; включает биотопливо. Jet/мазут: национальные сопоставимые цены не найдены; исходные значения сохранены. | AG24: Бензин: проверено GPP; Дизель: проверено GPP; LPG: н/д; Jet/керосин: нет сопоставимой национальной цены; Мазут: нет сопоставимой национальной цены | AH24: SR | AI24: SUR | AJ24: ='Сводка НПЗ'!D24 -> 1 | AK24: =IF('Сводка НПЗ'!F24>0,'Сводка НПЗ'!E24,"") -> 7000 | AL24: ='Сводка НПЗ'!G24 -> 0 | AM24: 2019-02-18 | AN24: Свежие число и мощность не подтверждены | AO24: 2024 | AP24: 2025 | AQ24: 2025 | AR24: 2026-09-16
